<?xml version="1.0"?>
<robot name="mantis_uav" xmlns:xacro="http://ros.org/wiki/xacro">
	<!-- Constants -->
	<xacro:property name="pi" value="3.1415926535897931"/>

	<!-- Import macros -->
	<xacro:include filename="$(find mantis_description)/urdf/base_quad_wire.xacro" />

	<xacro:include filename="$(find mantis_description)/urdf/slung_load_joint.xacro" />
	<xacro:include filename="$(find mantis_description)/urdf/slung_load_link.xacro" />

	<!-- Import all Gazebo-customization elements, including Gazebo colors -->
	<xacro:include filename="$(find mantis_description)/urdf/mantis.gazebo" />

	<!-- Used for fixing robot to Gazebo 'base_link' -->
	<link name="world"/>

	<joint name="fixed" type="floating">
		<parent link="world"/>
		<child link="base_link"/>
	</joint>

	<xacro:base_quad_wire arm_length="0.15" base_radius="0.075" mass="1.80497" ixx="0.02961" iyy="0.02933" izz="0.05342" ixy="0.0" ixz="0.00004" iyz="0.0" />

	<xacro:slung_load_joint suffix="wire_clip" parent="base_link" child="link_slung_load" xyz="0 0 -0.05025" rpy="${pi/2} ${pi/2} 0" />

	<xacro:slung_load_link suffix="slung_load" />
</robot>
