<?xml version='1.0'?>
<sdf version='1.6'>
  <model name='mantis_uav'>
    <link name='base_link'>
      <pose>0 0 0.5 0 0 0</pose>
      <gravity>1</gravity>
      <self_collide>0</self_collide>
      <kinematic>0</kinematic>

	  <inertial>
	    <!-- Mass of frame plates + PC + FC + Camera + GPS + PM + UBEC -->
        <mass>0.38</mass>
        <inertia>
          <ixx>0.0209475</ixx>
          <ixy>0</ixy>
          <ixz>0</ixz>
          <iyy>0.001075875</iyy>
          <iyz>0</iyz>
          <izz>0.001075875</izz>
        </inertia>
      </inertial>

      <collision name='collision_base_link'>
        <geometry>
          <cylinder>
            <radius>0.105</radius>
            <length>0.03</length>
          </cylinder>
        </geometry>
      </collision>

	  <visual name='visual_base_link'>
        <geometry>
          <cylinder>
            <radius>0.105</radius>
            <length>0.03</length>
          </cylinder>
        </geometry>
        <material>
          <lighting>1</lighting>
          <script>
            <uri>file://media/materials/scripts/gazebo.material</uri>
            <name>Gazebo/DarkGrey</name>
          </script>
        </material>
      </visual>
	</link>

	
    <link name="motor_arm_1">
      <pose>0 -0.19 0 1.5708 0 3.1416</pose>
      <gravity>1</gravity>
      <self_collide>0</self_collide>
      <kinematic>0</kinematic>

	  <inertial>
	    <!-- Mass of arm + ESC -->
        <mass>0.09</mass>
        <inertia>
          <ixx>0.0002218125</ixx>
          <ixy>0</ixy>
          <ixz>0</ixz>
          <iyy>0.0002218125</iyy>
          <iyz>0</iyz>
          <izz>0.000010125</izz>
        </inertia>
      </inertial>

      <collision name="collision_motor_arm_1">
        <geometry>
          <cylinder>
            <radius>0.015</radius>
            <length>0.17</length>
          </cylinder>
        </geometry>
      </collision>

      <visual name="visual_motor_arm_1">
        <geometry>
          <cylinder>
            <radius>0.015</radius>
            <length>0.17</length>
          </cylinder>
        </geometry>
        <material>
          <lighting>1</lighting>
          <script>
            <uri>file://media/materials/scripts/gazebo.material</uri>
            <name>Gazebo/White</name>
          </script>
        </material>
      </visual>
    </link>


	<joint type="fixed" name="joint_body_motor_arm_1">
      <parent>base_link</parent>
      <child>motor_arm_1</child>
    </joint>

	
    <link name="motor_arm_2">
      <pose>0 0.19 0 1.5708 0 0</pose>
      <gravity>1</gravity>
      <self_collide>0</self_collide>
      <kinematic>0</kinematic>

	  <inertial>
	    <!-- Mass of arm + ESC -->
        <mass>0.09</mass>
        <inertia>
          <ixx>0.0002218125</ixx>
          <ixy>0</ixy>
          <ixz>0</ixz>
          <iyy>0.0002218125</iyy>
          <iyz>0</iyz>
          <izz>0.000010125</izz>
        </inertia>
      </inertial>

      <collision name="collision_motor_arm_2">
        <geometry>
          <cylinder>
            <radius>0.015</radius>
            <length>0.17</length>
          </cylinder>
        </geometry>
      </collision>

      <visual name="visual_motor_arm_2">
        <geometry>
          <cylinder>
            <radius>0.015</radius>
            <length>0.17</length>
          </cylinder>
        </geometry>
        <material>
          <lighting>1</lighting>
          <script>
            <uri>file://media/materials/scripts/gazebo.material</uri>
            <name>Gazebo/White</name>
          </script>
        </material>
      </visual>
    </link>


	<joint type="fixed" name="joint_body_motor_arm_2">
      <parent>base_link</parent>
      <child>motor_arm_2</child>
    </joint>

	
    <link name="motor_arm_3">
      <pose>0.165 0.095 0 1.5708 0 2.0944</pose>
      <gravity>1</gravity>
      <self_collide>0</self_collide>
      <kinematic>0</kinematic>

	  <inertial>
	    <!-- Mass of arm + ESC -->
        <mass>0.09</mass>
        <inertia>
          <ixx>0.0002218125</ixx>
          <ixy>0</ixy>
          <ixz>0</ixz>
          <iyy>0.0002218125</iyy>
          <iyz>0</iyz>
          <izz>0.000010125</izz>
        </inertia>
      </inertial>

      <collision name="collision_motor_arm_3">
        <geometry>
          <cylinder>
            <radius>0.015</radius>
            <length>0.17</length>
          </cylinder>
        </geometry>
      </collision>

      <visual name="visual_motor_arm_3">
        <geometry>
          <cylinder>
            <radius>0.015</radius>
            <length>0.17</length>
          </cylinder>
        </geometry>
        <material>
          <lighting>1</lighting>
          <script>
            <uri>file://media/materials/scripts/gazebo.material</uri>
            <name>Gazebo/Red</name>
          </script>
        </material>
      </visual>
    </link>


	<joint type="fixed" name="joint_body_motor_arm_3">
      <parent>base_link</parent>
      <child>motor_arm_3</child>
    </joint>


    <link name="motor_arm_4">
      <pose>-0.165 -0.095 0 1.5708 0 2.0944</pose>
      <gravity>1</gravity>
      <self_collide>0</self_collide>
      <kinematic>0</kinematic>

	  <inertial>
	    <!-- Mass of arm + ESC -->
        <mass>0.09</mass>
        <inertia>
          <ixx>0.0002218125</ixx>
          <ixy>0</ixy>
          <ixz>0</ixz>
          <iyy>0.0002218125</iyy>
          <iyz>0</iyz>
          <izz>0.000010125</izz>
        </inertia>
      </inertial>

      <collision name="collision_motor_arm_4">
        <geometry>
          <cylinder>
            <radius>0.015</radius>
            <length>0.17</length>
          </cylinder>
        </geometry>
      </collision>

      <visual name="visual_motor_arm_4">
        <geometry>
          <cylinder>
            <radius>0.015</radius>
            <length>0.17</length>
          </cylinder>
        </geometry>
        <material>
          <lighting>1</lighting>
          <script>
            <uri>file://media/materials/scripts/gazebo.material</uri>
            <name>Gazebo/White</name>
          </script>
        </material>
      </visual>
    </link>


	<joint type="fixed" name="joint_body_motor_arm_4">
      <parent>base_link</parent>
      <child>motor_arm_4</child>
    </joint>

	
    <link name="motor_arm_5">
      <pose>0.165 -0.095 0 1.5708 0 1.0472</pose>
      <gravity>1</gravity>
      <self_collide>0</self_collide>
      <kinematic>0</kinematic>

	  <inertial>
	    <!-- Mass of arm + ESC -->
        <mass>0.09</mass>
        <inertia>
          <ixx>0.0002218125</ixx>
          <ixy>0</ixy>
          <ixz>0</ixz>
          <iyy>0.0002218125</iyy>
          <iyz>0</iyz>
          <izz>0.000010125</izz>
        </inertia>
      </inertial>

      <collision name="collision_motor_arm_5">
        <geometry>
          <cylinder>
            <radius>0.015</radius>
            <length>0.17</length>
          </cylinder>
        </geometry>
      </collision>

      <visual name="visual_motor_arm_5">
        <geometry>
          <cylinder>
            <radius>0.015</radius>
            <length>0.17</length>
          </cylinder>
        </geometry>
        <material>
          <lighting>1</lighting>
          <script>
            <uri>file://media/materials/scripts/gazebo.material</uri>
            <name>Gazebo/Red</name>
          </script>
        </material>
      </visual>
    </link>


	<joint type="fixed" name="joint_body_motor_arm_5">
      <parent>base_link</parent>
      <child>motor_arm_5</child>
    </joint>

	
    <link name="motor_arm_6">
      <pose>-0.165 0.095 0 1.5708 0 1.0472</pose>
      <gravity>1</gravity>
      <self_collide>0</self_collide>
      <kinematic>0</kinematic>

	  <inertial>
	    <!-- Mass of arm + ESC -->
        <mass>0.09</mass>
        <inertia>
          <ixx>0.0002218125</ixx>
          <ixy>0</ixy>
          <ixz>0</ixz>
          <iyy>0.0002218125</iyy>
          <iyz>0</iyz>
          <izz>0.000010125</izz>
        </inertia>
      </inertial>

      <collision name="collision_motor_arm_6">
        <geometry>
          <cylinder>
            <radius>0.015</radius>
            <length>0.17</length>
          </cylinder>
        </geometry>
      </collision>

      <visual name="visual_motor_arm_6">
        <geometry>
          <cylinder>
            <radius>0.015</radius>
            <length>0.17</length>
          </cylinder>
        </geometry>
        <material>
          <lighting>1</lighting>
          <script>
            <uri>file://media/materials/scripts/gazebo.material</uri>
            <name>Gazebo/White</name>
          </script>
        </material>
      </visual>
    </link>


	<joint type="fixed" name="joint_body_motor_arm_6">
      <parent>base_link</parent>
      <child>motor_arm_6</child>
    </joint>


<!-- TODO: Motors -->


<!-- TODO: Battery -->


    <link name='rotor_1'>
      <pose>0 -0.275 0.5455 0 0 0</pose>
      <gravity>1</gravity>
      <velocity_decay/>
      <self_collide>0</self_collide>

      <inertial>
        <mass>0.005</mass>
        <inertia>
          <ixx>9.75e-07</ixx>
          <ixy>0</ixy>
          <ixz>0</ixz>
          <iyy>0.000273104</iyy>
          <iyz>0</iyz>
          <izz>0.000274004</izz>
        </inertia>
      </inertial>

      <collision name='collision_rotor_1'>
        <geometry>
          <cylinder>
            <length>0.005</length>
            <radius>0.128</radius>
          </cylinder>
        </geometry>
      </collision>

      <visual name='visual_rotor_1'>
        <geometry>
          <box>
            <size>0.256 0.015 0.005</size>
          </box>
        </geometry>
        <material>
          <script>
            <name>Gazebo/Black</name>
            <uri>file://media/materials/scripts/gazebo.material</uri>
          </script>
        </material>
      </visual>
    </link>


    <joint type='revolute' name='joint_rotor_1'>
      <child>rotor_1</child>
      <parent>base_link</parent>
      <axis>
        <xyz>0 0 1</xyz>
        <limit>
          <lower>-1e+16</lower>
          <upper>1e+16</upper>
        </limit>
      </axis>
    </joint>


    <link name='rotor_2'>
      <pose>0 0.275 0.5455 0 0 0</pose>
      <gravity>1</gravity>
      <velocity_decay/>
      <self_collide>0</self_collide>

      <inertial>
        <mass>0.005</mass>
        <inertia>
          <ixx>9.75e-07</ixx>
          <ixy>0</ixy>
          <ixz>0</ixz>
          <iyy>0.000273104</iyy>
          <iyz>0</iyz>
          <izz>0.000274004</izz>
        </inertia>
      </inertial>

      <collision name='collision_rotor_2'>
        <geometry>
          <cylinder>
            <length>0.005</length>
            <radius>0.128</radius>
          </cylinder>
        </geometry>
      </collision>

      <visual name='visual_rotor_2'>
        <geometry>
          <box>
            <size>0.256 0.015 0.005</size>
          </box>
        </geometry>
        <material>
          <script>
            <name>Gazebo/Black</name>
            <uri>file://media/materials/scripts/gazebo.material</uri>
          </script>
        </material>
      </visual>
    </link>


    <joint type='revolute' name='joint_rotor_2'>
      <child>rotor_2</child>
      <parent>base_link</parent>
      <axis>
        <xyz>0 0 1</xyz>
        <limit>
          <lower>-1e+16</lower>
          <upper>1e+16</upper>
        </limit>
      </axis>
    </joint>


    <link name='rotor_3'>
      <pose>0.2382 0.1375 0.5455 0 0 0</pose>
      <gravity>1</gravity>
      <velocity_decay/>
      <self_collide>0</self_collide>

      <inertial>
        <mass>0.005</mass>
        <inertia>
          <ixx>9.75e-07</ixx>
          <ixy>0</ixy>
          <ixz>0</ixz>
          <iyy>0.000273104</iyy>
          <iyz>0</iyz>
          <izz>0.000274004</izz>
        </inertia>
      </inertial>

      <collision name='collision_rotor_3'>
        <geometry>
          <cylinder>
            <length>0.005</length>
            <radius>0.128</radius>
          </cylinder>
        </geometry>
      </collision>

      <visual name='visual_rotor_3'>
        <geometry>
          <box>
            <size>0.256 0.015 0.005</size>
          </box>
        </geometry>
        <material>
          <script>
            <name>Gazebo/Black</name>
            <uri>file://media/materials/scripts/gazebo.material</uri>
          </script>
        </material>
      </visual>
    </link>


    <joint type='revolute' name='joint_rotor_3'>
      <child>rotor_3</child>
      <parent>base_link</parent>
      <axis>
        <xyz>0 0 1</xyz>
        <limit>
          <lower>-1e+16</lower>
          <upper>1e+16</upper>
        </limit>
      </axis>
    </joint>


    <link name='rotor_4'>
      <pose>-0.2382 -0.1375 0.5455 0 0 0</pose>
      <gravity>1</gravity>
      <velocity_decay/>
      <self_collide>0</self_collide>

      <inertial>
        <mass>0.005</mass>
        <inertia>
          <ixx>9.75e-07</ixx>
          <ixy>0</ixy>
          <ixz>0</ixz>
          <iyy>0.000273104</iyy>
          <iyz>0</iyz>
          <izz>0.000274004</izz>
        </inertia>
      </inertial>

      <collision name='collision_rotor_4'>
        <geometry>
          <cylinder>
            <length>0.005</length>
            <radius>0.128</radius>
          </cylinder>
        </geometry>
      </collision>

      <visual name='visual_rotor_4'>
        <geometry>
          <box>
            <size>0.256 0.015 0.005</size>
          </box>
        </geometry>
        <material>
          <script>
            <name>Gazebo/Black</name>
            <uri>file://media/materials/scripts/gazebo.material</uri>
          </script>
        </material>
      </visual>
    </link>


    <joint type='revolute' name='joint_rotor_4'>
      <child>rotor_4</child>
      <parent>base_link</parent>
      <axis>
        <xyz>0 0 1</xyz>
        <limit>
          <lower>-1e+16</lower>
          <upper>1e+16</upper>
        </limit>
      </axis>
    </joint>


    <link name='rotor_5'>
      <pose>0.2382 -0.1375 0.5455 0 0 0</pose>
      <gravity>1</gravity>
      <velocity_decay/>
      <self_collide>0</self_collide>

      <inertial>
        <mass>0.005</mass>
        <inertia>
          <ixx>9.75e-07</ixx>
          <ixy>0</ixy>
          <ixz>0</ixz>
          <iyy>0.000273104</iyy>
          <iyz>0</iyz>
          <izz>0.000274004</izz>
        </inertia>
      </inertial>

      <collision name='collision_rotor_5'>
        <geometry>
          <cylinder>
            <length>0.005</length>
            <radius>0.128</radius>
          </cylinder>
        </geometry>
      </collision>

      <visual name='visual_rotor_5'>
        <geometry>
          <box>
            <size>0.256 0.015 0.005</size>
          </box>
        </geometry>
        <material>
          <script>
            <name>Gazebo/Black</name>
            <uri>file://media/materials/scripts/gazebo.material</uri>
          </script>
        </material>
      </visual>
    </link>


    <joint type='revolute' name='joint_rotor_5'>
      <child>rotor_5</child>
      <parent>base_link</parent>
      <axis>
        <xyz>0 0 1</xyz>
        <limit>
          <lower>-1e+16</lower>
          <upper>1e+16</upper>
        </limit>
      </axis>
    </joint>


    <link name='rotor_6'>
      <pose>-0.2382 0.1375 0.5455 0 0 0</pose>
      <gravity>1</gravity>
      <velocity_decay/>
      <self_collide>0</self_collide>

      <inertial>
        <mass>0.005</mass>
        <inertia>
          <ixx>9.75e-07</ixx>
          <ixy>0</ixy>
          <ixz>0</ixz>
          <iyy>0.000273104</iyy>
          <iyz>0</iyz>
          <izz>0.000274004</izz>
        </inertia>
      </inertial>

      <collision name='collision_rotor_6'>
        <geometry>
          <cylinder>
            <length>0.005</length>
            <radius>0.128</radius>
          </cylinder>
        </geometry>
      </collision>

      <visual name='visual_rotor_6'>
        <geometry>
          <box>
            <size>0.256 0.015 0.005</size>
          </box>
        </geometry>
        <material>
          <script>
            <name>Gazebo/Black</name>
            <uri>file://media/materials/scripts/gazebo.material</uri>
          </script>
        </material>
      </visual>
    </link>


    <joint type='revolute' name='joint_rotor_6'>
      <child>rotor_6</child>
      <parent>base_link</parent>
      <axis>
        <xyz>0 0 1</xyz>
        <limit>
          <lower>-1e+16</lower>
          <upper>1e+16</upper>
        </limit>
      </axis>
    </joint>


    <link name="landing_gear_1">
      <pose>0 -0.275 0.425 0 0 0</pose>
      <gravity>1</gravity>
      <self_collide>0</self_collide>
      <kinematic>0</kinematic>

	  <inertial>
        <mass>0.008</mass>
        <inertia>
          <ixx>0.000010504</ixx>
          <ixy>0</ixy>
          <ixz>0</ixz>
          <iyy>0.000010504</iyy>
          <iyz>0</iyz>
          <izz>0.000001808</izz>
        </inertia>
      </inertial>

      <collision name="collision_landing_gear_1">
        <geometry>
          <cylinder>
            <radius>0.008</radius>
            <length>0.12</length>
          </cylinder>
        </geometry>
      </collision>

      <visual name="visual_landing_gear_1">
        <geometry>
          <cylinder>
            <radius>0.008</radius>
            <length>0.12</length>
          </cylinder>
        </geometry>
      </visual>
    </link>


	<joint type="fixed" name="joint_body_landing_gear_1">
      <parent>base_link</parent>
      <child>landing_gear_1</child>
    </joint>


    <link name="landing_gear_2">
      <pose>0 0.275 0.425 0 0 0</pose>
      <gravity>1</gravity>
      <self_collide>0</self_collide>
      <kinematic>0</kinematic>

	  <inertial>
        <mass>0.008</mass>
        <inertia>
          <ixx>0.000010504</ixx>
          <ixy>0</ixy>
          <ixz>0</ixz>
          <iyy>0.000010504</iyy>
          <iyz>0</iyz>
          <izz>0.000001808</izz>
        </inertia>
      </inertial>

      <collision name="collision_landing_gear_2">
        <geometry>
          <cylinder>
            <radius>0.008</radius>
            <length>0.12</length>
          </cylinder>
        </geometry>
      </collision>

      <visual name="visual_landing_gear_2">
        <geometry>
          <cylinder>
            <radius>0.008</radius>
            <length>0.12</length>
          </cylinder>
        </geometry>
      </visual>
    </link>


	<joint type="fixed" name="joint_body_landing_gear_2">
      <parent>base_link</parent>
      <child>landing_gear_2</child>
    </joint>


    <link name="landing_gear_3">
      <pose>0.2382 0.1375 0.425 0 0 0</pose>
      <gravity>1</gravity>
      <self_collide>0</self_collide>
      <kinematic>0</kinematic>

	  <inertial>
        <mass>0.008</mass>
        <inertia>
          <ixx>0.000010504</ixx>
          <ixy>0</ixy>
          <ixz>0</ixz>
          <iyy>0.000010504</iyy>
          <iyz>0</iyz>
          <izz>0.000001808</izz>
        </inertia>
      </inertial>

      <collision name="collision_landing_gear_3">
        <geometry>
          <cylinder>
            <radius>0.008</radius>
            <length>0.12</length>
          </cylinder>
        </geometry>
      </collision>

      <visual name="visual_landing_gear_3">
        <geometry>
          <cylinder>
            <radius>0.008</radius>
            <length>0.12</length>
          </cylinder>
        </geometry>
      </visual>
    </link>


	<joint type="fixed" name="joint_body_landing_gear_3">
      <parent>base_link</parent>
      <child>landing_gear_3</child>
    </joint>


    <link name="landing_gear_4">
      <pose>-0.2382 -0.1375 0.425 0 0 0</pose>
      <gravity>1</gravity>
      <self_collide>0</self_collide>
      <kinematic>0</kinematic>

	  <inertial>
        <mass>0.008</mass>
        <inertia>
          <ixx>0.000010504</ixx>
          <ixy>0</ixy>
          <ixz>0</ixz>
          <iyy>0.000010504</iyy>
          <iyz>0</iyz>
          <izz>0.000001808</izz>
        </inertia>
      </inertial>

      <collision name="collision_landing_gear_4">
        <geometry>
          <cylinder>
            <radius>0.008</radius>
            <length>0.12</length>
          </cylinder>
        </geometry>
      </collision>

      <visual name="visual_landing_gear_4">
        <geometry>
          <cylinder>
            <radius>0.008</radius>
            <length>0.12</length>
          </cylinder>
        </geometry>
      </visual>
    </link>


	<joint type="fixed" name="joint_body_landing_gear_4">
      <parent>base_link</parent>
      <child>landing_gear_4</child>
    </joint>


    <link name="landing_gear_5">
      <pose>0.2382 -0.1375 0.425 0 0 0</pose>
      <gravity>1</gravity>
      <self_collide>0</self_collide>
      <kinematic>0</kinematic>

	  <inertial>
        <mass>0.008</mass>
        <inertia>
          <ixx>0.000010504</ixx>
          <ixy>0</ixy>
          <ixz>0</ixz>
          <iyy>0.000010504</iyy>
          <iyz>0</iyz>
          <izz>0.000001808</izz>
        </inertia>
      </inertial>

      <collision name="collision_landing_gear_5">
        <geometry>
          <cylinder>
            <radius>0.008</radius>
            <length>0.12</length>
          </cylinder>
        </geometry>
      </collision>

      <visual name="visual_landing_gear_5">
        <geometry>
          <cylinder>
            <radius>0.008</radius>
            <length>0.12</length>
          </cylinder>
        </geometry>
      </visual>
    </link>


	<joint type="fixed" name="joint_body_landing_gear_5">
      <parent>base_link</parent>
      <child>landing_gear_5</child>
    </joint>


    <link name="landing_gear_6">
      <pose>-0.2382 0.1375 0.425 0 0 0</pose>
      <gravity>1</gravity>
      <self_collide>0</self_collide>
      <kinematic>0</kinematic>

	  <inertial>
        <mass>0.008</mass>
        <inertia>
          <ixx>0.000010504</ixx>
          <ixy>0</ixy>
          <ixz>0</ixz>
          <iyy>0.000010504</iyy>
          <iyz>0</iyz>
          <izz>0.000001808</izz>
        </inertia>
      </inertial>

      <collision name="collision_landing_gear_6">
        <geometry>
          <cylinder>
            <radius>0.008</radius>
            <length>0.12</length>
          </cylinder>
        </geometry>
      </collision>

      <visual name="visual_landing_gear_6">
        <geometry>
          <cylinder>
            <radius>0.008</radius>
            <length>0.12</length>
          </cylinder>
        </geometry>
      </visual>
    </link>


	<joint type="fixed" name="joint_body_landing_gear_6">
      <parent>base_link</parent>
      <child>landing_gear_6</child>
    </joint>


	<joint type="fixed" name="joint_body_shoulder">
      <parent>base_link</parent>
      <child>arm_link_shoulder</child>
    </joint>


    <link name="arm_link_shoulder">
      <pose>0 0 0.46175 0 0 0</pose>
      <gravity>1</gravity>
      <self_collide>0</self_collide>
      <kinematic>0</kinematic>

	  <inertial>
        <mass>0.082</mass>
        <inertia>
          <ixx>0.000022675</ixx>
          <ixy>0</ixy>
          <ixz>0</ixz>
          <iyy>0.000020326</iyy>
          <iyz>0</iyz>
          <izz>0.00001345</izz>
        </inertia>
      </inertial>

      <collision name="collision_shoulder">
        <geometry>
          <box>
            <size>0.0285 0.034 0.0465</size>
          </box>
        </geometry>
      </collision>

      <visual name="visual_shoulder">
        <geometry>
          <box>
            <size>0.0285 0.034 0.0465</size>
          </box>
        </geometry>
      </visual>
    </link>


	<joint type="revolute" name="joint_shoulder_upperarm_servo">
      <pose>0 0 0.09 0 0 0</pose>
      <parent>arm_link_shoulder</parent>
      <child>arm_link_upperarm</child>
      <axis>
        <xyz>0 1 0</xyz>
        <dynamics>
          <friction>0</friction>
        </dynamics>
        <limit>
          <lower>-1.57</lower>
          <upper>1.57</upper>
        </limit>
      </axis>
    </joint>


    <link name="arm_link_upperarm">
      <pose>0 0 0.35975 0 0 0</pose>
      <gravity>1</gravity>
      <self_collide>0</self_collide>
      <kinematic>0</kinematic>

	  <inertial>
        <mass>0.008</mass>
        <inertia>
          <ixx>0.000010504</ixx>
          <ixy>0</ixy>
          <ixz>0</ixz>
          <iyy>0.000010504</iyy>
          <iyz>0</iyz>
          <izz>0.000001808</izz>
        </inertia>
      </inertial>

      <collision name="collision_upperarm">
        <geometry>
          <cylinder>
            <radius>0.008</radius>
            <length>0.12</length>
          </cylinder>
        </geometry>
      </collision>

      <visual name="visual_upperarm">
        <geometry>
          <cylinder>
            <radius>0.008</radius>
            <length>0.12</length>
          </cylinder>
        </geometry>
      </visual>
    </link>


	<joint type="fixed" name="joint_upperarm_elbow">
      <parent>arm_link_upperarm</parent>
      <child>arm_link_elbow_servo</child>
    </joint>


    <link name="arm_link_elbow_servo">
      <pose>0 0 0.2765 0 0 0</pose>
      <gravity>1</gravity>
      <self_collide>0</self_collide>
      <kinematic>0</kinematic>

	  <inertial>
        <mass>0.082</mass>
        <inertia>
          <ixx>0.000022675</ixx>
          <ixy>0</ixy>
          <ixz>0</ixz>
          <iyy>0.000020326</iyy>
          <iyz>0</iyz>
          <izz>0.00001345</izz>
        </inertia>
      </inertial>

      <collision name="collision_elbow_servo">
        <geometry>
          <box>
            <size>0.0285 0.034 0.0465</size>
          </box>
        </geometry>
      </collision>

      <visual name="visual_elbow_servo">
        <geometry>
          <box>
            <size>0.0285 0.034 0.0465</size>
          </box>
        </geometry>
      </visual>
    </link>


	<joint type="revolute" name="joint_elbow_forearm_servo">
      <pose>0 0 0.09 0 0 0</pose>
      <parent>arm_link_elbow_servo</parent>
      <child>arm_link_forearm</child>
      <axis>
        <xyz>0 1 0</xyz>
        <dynamics>
          <friction>0</friction>
        </dynamics>
        <limit>
          <lower>-1.57</lower>
          <upper>1.57</upper>
        </limit>
      </axis>
    </joint>


    <link name="arm_link_forearm">
      <pose>0 0 0.1745 0 0 0</pose>
      <gravity>1</gravity>
      <self_collide>0</self_collide>
      <kinematic>0</kinematic>

	  <inertial>
        <mass>0.008</mass>
        <inertia>
          <ixx>0.000010504</ixx>
          <ixy>0</ixy>
          <ixz>0</ixz>
          <iyy>0.000010504</iyy>
          <iyz>0</iyz>
          <izz>0.000001808</izz>
        </inertia>
      </inertial>

      <collision name="collision_forearm">
        <geometry>
          <cylinder>
            <radius>0.008</radius>
            <length>0.12</length>
          </cylinder>
        </geometry>
      </collision>

      <visual name="visual_forearm">
        <geometry>
          <cylinder>
            <radius>0.008</radius>
            <length>0.12</length>
          </cylinder>
        </geometry>
      </visual>
    </link>


    <plugin name="mantis_gazebo_servo" filename="libmantis_gazebo_servo.so"/>
    <!-- TODO: PARAMETERS! -->

    <plugin name="mantis_gazebo_pwm" filename="libmantis_gazebo_pwm_motor.so"/>
    <!-- TODO: PARAMETERS! -->

	<plugin name='mantis_gazebo_motor_model_1' filename='libmantis_gazebo_motor_model.so'>
      <robotNamespace></robotNamespace>
      <jointName>joint_rotor_1</jointName>
      <linkName>rotor_1</linkName>
      <turningDirection>cw</turningDirection>
      <timeConstantUp>0.0125</timeConstantUp>
      <timeConstantDown>0.025</timeConstantDown>
      <maxRotVelocity>1500</maxRotVelocity>
      <motorConstant>8.54858e-06</motorConstant>
      <momentConstant>0.06</momentConstant>
      <commandSubTopic>/command/motor_velocity</commandSubTopic>
      <motorNumber>0</motorNumber>
      <rotorDragCoefficient>0.000806428</rotorDragCoefficient>
      <rollingMomentCoefficient>1e-06</rollingMomentCoefficient>
      <motorSpeedPubTopic>/state/motor_speed/1</motorSpeedPubTopic>
      <rotorVelocitySlowdownSim>10</rotorVelocitySlowdownSim>
    </plugin>

	<plugin name='mantis_gazebo_motor_model_2' filename='libmantis_gazebo_motor_model.so'>
      <robotNamespace></robotNamespace>
      <jointName>joint_rotor_2</jointName>
      <linkName>rotor_2</linkName>
      <turningDirection>ccw</turningDirection>
      <timeConstantUp>0.0125</timeConstantUp>
      <timeConstantDown>0.025</timeConstantDown>
      <maxRotVelocity>1500</maxRotVelocity>
      <motorConstant>8.54858e-06</motorConstant>
      <momentConstant>0.06</momentConstant>
      <commandSubTopic>/command/motor_velocity</commandSubTopic>
      <motorNumber>1</motorNumber>
      <rotorDragCoefficient>0.000806428</rotorDragCoefficient>
      <rollingMomentCoefficient>1e-06</rollingMomentCoefficient>
      <motorSpeedPubTopic>/state/motor_speed/2</motorSpeedPubTopic>
      <rotorVelocitySlowdownSim>10</rotorVelocitySlowdownSim>
    </plugin>

	<plugin name='mantis_gazebo_motor_model_3' filename='libmantis_gazebo_motor_model.so'>
      <robotNamespace></robotNamespace>
      <jointName>joint_rotor_3</jointName>
      <linkName>rotor_3</linkName>
      <turningDirection>cw</turningDirection>
      <timeConstantUp>0.0125</timeConstantUp>
      <timeConstantDown>0.025</timeConstantDown>
      <maxRotVelocity>1500</maxRotVelocity>
      <motorConstant>8.54858e-06</motorConstant>
      <momentConstant>0.06</momentConstant>
      <commandSubTopic>/command/motor_velocity</commandSubTopic>
      <motorNumber>2</motorNumber>
      <rotorDragCoefficient>0.000806428</rotorDragCoefficient>
      <rollingMomentCoefficient>1e-06</rollingMomentCoefficient>
      <motorSpeedPubTopic>/state/motor_speed/3</motorSpeedPubTopic>
      <rotorVelocitySlowdownSim>10</rotorVelocitySlowdownSim>
    </plugin>

	<plugin name='mantis_gazebo_motor_model_4' filename='libmantis_gazebo_motor_model.so'>
      <robotNamespace></robotNamespace>
      <jointName>joint_rotor_4</jointName>
      <linkName>rotor_4</linkName>
      <turningDirection>ccw</turningDirection>
      <timeConstantUp>0.0125</timeConstantUp>
      <timeConstantDown>0.025</timeConstantDown>
      <maxRotVelocity>1500</maxRotVelocity>
      <motorConstant>8.54858e-06</motorConstant>
      <momentConstant>0.06</momentConstant>
      <commandSubTopic>/command/motor_velocity</commandSubTopic>
      <motorNumber>3</motorNumber>
      <rotorDragCoefficient>0.000806428</rotorDragCoefficient>
      <rollingMomentCoefficient>1e-06</rollingMomentCoefficient>
      <motorSpeedPubTopic>/state/motor_speed/4</motorSpeedPubTopic>
      <rotorVelocitySlowdownSim>10</rotorVelocitySlowdownSim>
    </plugin>

	<plugin name='mantis_gazebo_motor_model_5' filename='libmantis_gazebo_motor_model.so'>
      <robotNamespace></robotNamespace>
      <jointName>joint_rotor_5</jointName>
      <linkName>rotor_5</linkName>
      <turningDirection>ccw</turningDirection>
      <timeConstantUp>0.0125</timeConstantUp>
      <timeConstantDown>0.025</timeConstantDown>
      <maxRotVelocity>1500</maxRotVelocity>
      <motorConstant>8.54858e-06</motorConstant>
      <momentConstant>0.06</momentConstant>
      <commandSubTopic>/command/motor_velocity</commandSubTopic>
      <motorNumber>4</motorNumber>
      <rotorDragCoefficient>0.000806428</rotorDragCoefficient>
      <rollingMomentCoefficient>1e-06</rollingMomentCoefficient>
      <motorSpeedPubTopic>/state/motor_speed/5</motorSpeedPubTopic>
      <rotorVelocitySlowdownSim>10</rotorVelocitySlowdownSim>
    </plugin>

	<plugin name='mantis_gazebo_motor_model_6' filename='libmantis_gazebo_motor_model.so'>
      <robotNamespace></robotNamespace>
      <jointName>joint_rotor_6</jointName>
      <linkName>rotor_6</linkName>
      <turningDirection>cw</turningDirection>
      <timeConstantUp>0.0125</timeConstantUp>
      <timeConstantDown>0.025</timeConstantDown>
      <maxRotVelocity>1500</maxRotVelocity>
      <motorConstant>8.54858e-06</motorConstant>
      <momentConstant>0.06</momentConstant>
      <commandSubTopic>/command/motor_velocity</commandSubTopic>
      <motorNumber>5</motorNumber>
      <rotorDragCoefficient>0.000806428</rotorDragCoefficient>
      <rollingMomentCoefficient>1e-06</rollingMomentCoefficient>
      <motorSpeedPubTopic>/state/motor_speed/6</motorSpeedPubTopic>
      <rotorVelocitySlowdownSim>10</rotorVelocitySlowdownSim>
    </plugin>

    <static>false</static>
    <allow_auto_disable>1</allow_auto_disable>
  </model>
</sdf>
