<?xml version='1.0'?>
<sdf version='1.6'>
  <model name='mantis_uav'>
    <link name='base_link'>
      <pose>0 0 0.5 0 0 0</pose>
      <gravity>1</gravity>
      <self_collide>0</self_collide>
      <kinematic>0</kinematic>

	  <inertial>
        <mass>1.5480</mass>
        <inertia>
          <ixx>0.015198135489664</ixx>
          <ixy>0</ixy>
          <ixz>-1.192366728849071e-19</ixz>
          <iyy>0.014353211169664</iyy>
          <iyz>9.175993298526920e-20</iyz>
          <izz>0.027767959346667</izz>
        </inertia>
      </inertial>

      <collision name='collision_base_link'>
        <geometry>
          <cylinder>
            <radius>0.275</radius>
            <length>0.03</length>
          </cylinder>
        </geometry>
      </collision>

	  <visual name='visual_base_link'>
        <geometry>
          <cylinder>
            <radius>0.105</radius>
            <length>0.03</length>
          </cylinder>
        </geometry>
        <material>
          <lighting>1</lighting>
          <script>
            <uri>file://media/materials/scripts/gazebo.material</uri>
            <name>Gazebo/DarkGrey</name>
          </script>
        </material>
      </visual>

      <visual name="visual_motor_arm_1">
        <pose>0 -0.19 0 1.5708 0 3.1416</pose>
        <geometry>
          <cylinder>
            <radius>0.015</radius>
            <length>0.17</length>
          </cylinder>
        </geometry>
        <material>
          <lighting>1</lighting>
          <script>
            <uri>file://media/materials/scripts/gazebo.material</uri>
            <name>Gazebo/White</name>
          </script>
        </material>
      </visual>

      <visual name="visual_motor_arm_2">
        <pose>0 0.19 0 1.5708 0 0</pose>
        <geometry>
          <cylinder>
            <radius>0.015</radius>
            <length>0.17</length>
          </cylinder>
        </geometry>
        <material>
          <lighting>1</lighting>
          <script>
            <uri>file://media/materials/scripts/gazebo.material</uri>
            <name>Gazebo/White</name>
          </script>
        </material>
      </visual>

      <visual name="visual_motor_arm_3">
        <pose>0.165 0.095 0 1.5708 0 2.0944</pose>
        <geometry>
          <cylinder>
            <radius>0.015</radius>
            <length>0.17</length>
          </cylinder>
        </geometry>
        <material>
          <lighting>1</lighting>
          <script>
            <uri>file://media/materials/scripts/gazebo.material</uri>
            <name>Gazebo/Red</name>
          </script>
        </material>
      </visual>

      <visual name="visual_motor_arm_4">
        <pose>-0.165 -0.095 0 1.5708 0 2.0944</pose>
        <geometry>
          <cylinder>
            <radius>0.015</radius>
            <length>0.17</length>
          </cylinder>
        </geometry>
        <material>
          <lighting>1</lighting>
          <script>
            <uri>file://media/materials/scripts/gazebo.material</uri>
            <name>Gazebo/White</name>
          </script>
        </material>
      </visual>

      <visual name="visual_motor_arm_5">
        <pose>0.165 -0.095 0 1.5708 0 1.0472</pose>
        <geometry>
          <cylinder>
            <radius>0.015</radius>
            <length>0.17</length>
          </cylinder>
        </geometry>
        <material>
          <lighting>1</lighting>
          <script>
            <uri>file://media/materials/scripts/gazebo.material</uri>
            <name>Gazebo/Red</name>
          </script>
        </material>
      </visual>

      <visual name="visual_motor_arm_6">
        <pose>-0.165 0.095 0 1.5708 0 1.0472</pose>
        <geometry>
          <cylinder>
            <radius>0.015</radius>
            <length>0.17</length>
          </cylinder>
        </geometry>
        <material>
          <lighting>1</lighting>
          <script>
            <uri>file://media/materials/scripts/gazebo.material</uri>
            <name>Gazebo/White</name>
          </script>
        </material>
      </visual>

      <visual name="visual_motor_1">
        <pose>0 -0.275 0.027 0 0 0</pose>
        <geometry>
          <cylinder>
            <radius>0.014</radius>
            <length>0.024</length>
          </cylinder>
        </geometry>
        <material>
          <lighting>1</lighting>
          <script>
            <uri>file://media/materials/scripts/gazebo.material</uri>
            <name>Gazebo/DarkGrey</name>
          </script>
        </material>
      </visual>

      <visual name="visual_motor_2">
        <pose>0 0.275 0.027 0 0 0</pose>
        <geometry>
          <cylinder>
            <radius>0.014</radius>
            <length>0.024</length>
          </cylinder>
        </geometry>
        <material>
          <lighting>1</lighting>
          <script>
            <uri>file://media/materials/scripts/gazebo.material</uri>
            <name>Gazebo/DarkGrey</name>
          </script>
        </material>
      </visual>

      <visual name="visual_motor_3">
        <pose>0.2382 0.1375 0.027 0 0 0</pose>
        <geometry>
          <cylinder>
            <radius>0.014</radius>
            <length>0.024</length>
          </cylinder>
        </geometry>
        <material>
          <lighting>1</lighting>
          <script>
            <uri>file://media/materials/scripts/gazebo.material</uri>
            <name>Gazebo/DarkGrey</name>
          </script>
        </material>
      </visual>

      <visual name="visual_motor_4">
        <pose>-0.2382 -0.1375 0.027 0 0 0</pose>
        <geometry>
          <cylinder>
            <radius>0.014</radius>
            <length>0.024</length>
          </cylinder>
        </geometry>
        <material>
          <lighting>1</lighting>
          <script>
            <uri>file://media/materials/scripts/gazebo.material</uri>
            <name>Gazebo/DarkGrey</name>
          </script>
        </material>
      </visual>

      <visual name="visual_motor_5">
        <pose>0.2382 -0.1375 0.027 0 0 0</pose>
        <geometry>
          <cylinder>
            <radius>0.014</radius>
            <length>0.024</length>
          </cylinder>
        </geometry>
        <material>
          <lighting>1</lighting>
          <script>
            <uri>file://media/materials/scripts/gazebo.material</uri>
            <name>Gazebo/DarkGrey</name>
          </script>
        </material>
      </visual>

      <visual name="visual_motor_6">
        <pose>-0.2382 0.1375 0.027 0 0 0</pose>
        <geometry>
          <cylinder>
            <radius>0.014</radius>
            <length>0.024</length>
          </cylinder>
        </geometry>
        <material>
          <lighting>1</lighting>
          <script>
            <uri>file://media/materials/scripts/gazebo.material</uri>
            <name>Gazebo/DarkGrey</name>
          </script>
        </material>
      </visual>

      <collision name="collision_skid_1">
        <pose>0 -0.275 -0.075 0 0 0</pose>
        <geometry>
          <cylinder>
            <radius>0.008</radius>
            <length>0.12</length>
          </cylinder>
        </geometry>
      </collision>

      <visual name="visual_skid_1">
        <pose>0 -0.275 -0.075 0 0 0</pose>
        <geometry>
          <cylinder>
            <radius>0.008</radius>
            <length>0.12</length>
          </cylinder>
        </geometry>
        <material>
          <lighting>1</lighting>
          <script>
            <uri>file://media/materials/scripts/gazebo.material</uri>
            <name>Gazebo/White</name>
          </script>
        </material>
      </visual>

      <collision name="collision_skid_2">
        <pose>0 0.275 -0.075 0 0 0</pose>
        <geometry>
          <cylinder>
            <radius>0.008</radius>
            <length>0.12</length>
          </cylinder>
        </geometry>
      </collision>

      <visual name="visual_skid_2">
        <pose>0 0.275 -0.075 0 0 0</pose>
        <geometry>
          <cylinder>
            <radius>0.008</radius>
            <length>0.12</length>
          </cylinder>
        </geometry>
        <material>
          <lighting>1</lighting>
          <script>
            <uri>file://media/materials/scripts/gazebo.material</uri>
            <name>Gazebo/White</name>
          </script>
        </material>
      </visual>

      <collision name="collision_skid_3">
        <pose>0.2382 0.1375 -0.075 0 0 0</pose>
        <geometry>
          <cylinder>
            <radius>0.008</radius>
            <length>0.12</length>
          </cylinder>
        </geometry>
      </collision>

      <visual name="visual_skid_3">
        <pose>0.2382 0.1375 -0.075 0 0 0</pose>
        <geometry>
          <cylinder>
            <radius>0.008</radius>
            <length>0.12</length>
          </cylinder>
        </geometry>
        <material>
          <lighting>1</lighting>
          <script>
            <uri>file://media/materials/scripts/gazebo.material</uri>
            <name>Gazebo/White</name>
          </script>
        </material>
      </visual>

      <collision name="collision_skid_4">
        <pose>-0.2382 -0.1375 -0.075 0 0 0</pose>
        <geometry>
          <cylinder>
            <radius>0.008</radius>
            <length>0.12</length>
          </cylinder>
        </geometry>
      </collision>

      <visual name="visual_skid_4">
        <pose>-0.2382 -0.1375 -0.075 0 0 0</pose>
        <geometry>
          <cylinder>
            <radius>0.008</radius>
            <length>0.12</length>
          </cylinder>
        </geometry>
        <material>
          <lighting>1</lighting>
          <script>
            <uri>file://media/materials/scripts/gazebo.material</uri>
            <name>Gazebo/White</name>
          </script>
        </material>
      </visual>

      <collision name="collision_skid_5">
        <pose>0.2382 -0.1375 -0.075 0 0 0</pose>
        <geometry>
          <cylinder>
            <radius>0.008</radius>
            <length>0.12</length>
          </cylinder>
        </geometry>
      </collision>

      <visual name="visual_skid_5">
        <pose>0.2382 -0.1375 -0.075 0 0 0</pose>
        <geometry>
          <cylinder>
            <radius>0.008</radius>
            <length>0.12</length>
          </cylinder>
        </geometry>
        <material>
          <lighting>1</lighting>
          <script>
            <uri>file://media/materials/scripts/gazebo.material</uri>
            <name>Gazebo/White</name>
          </script>
        </material>
      </visual>

      <collision name="collision_skid_6">
        <pose>-0.2382 0.1375 -0.075 0 0 0</pose>
        <geometry>
          <cylinder>
            <radius>0.008</radius>
            <length>0.12</length>
          </cylinder>
        </geometry>
      </collision>

      <visual name="visual_skid_6">
        <pose>-0.2382 0.1375 -0.075 0 0 0</pose>
        <geometry>
          <cylinder>
            <radius>0.008</radius>
            <length>0.12</length>
          </cylinder>
        </geometry>
        <material>
          <lighting>1</lighting>
          <script>
            <uri>file://media/materials/scripts/gazebo.material</uri>
            <name>Gazebo/White</name>
          </script>
        </material>
      </visual>

      <collision name="collision_battery">
        <pose>0 0 0.032 0 0 0</pose>
        <geometry>
          <box>
            <size>0.052 0.146 0.034</size>
          </box>
        </geometry>
      </collision>

      <visual name="visual_battery">
        <pose>0 0 0.032 0 0 0</pose>
        <geometry>
          <box>
            <size>0.052 0.146 0.034</size>
          </box>
        </geometry>
        <material>
          <lighting>1</lighting>
          <script>
            <uri>file://media/materials/scripts/gazebo.material</uri>
            <name>Gazebo/Blue</name>
          </script>
        </material>
      </visual>

	  <collision name="collision_shoulder_servo">
        <pose>0 0 -0.03825 0 0 0</pose>
        <geometry>
          <box>
            <size>0.0285 0.034 0.0465</size>
          </box>
        </geometry>
      </collision>

      <visual name="visual_shoulder_servo">
        <pose>0.01425 0.019 -0.015 -1.570796327 0 3.141592654</pose>
        <geometry>
		  <mesh>
			<uri>model://mantis_uav/meshes/X-430_IDLE.stl</uri>
			<scale>0.001 0.001 0.001</scale>
		  </mesh>
        </geometry>
        <material>
          <lighting>1</lighting>
          <script>
            <uri>file://media/materials/scripts/gazebo.material</uri>
            <name>Gazebo/DarkGrey</name>
          </script>
        </material>
      </visual>
	</link>


	<joint type="revolute" name="joint_shoulder">
      <pose>-0.15047991 0 0 0 0 0</pose>
      <parent>base_link</parent>
      <child>arm_link_upperarm</child>
      <axis>
        <xyz>0 0 1</xyz>
        <dynamics>
          <damping>0.01</damping>
          <spring_reference>0.0</spring_reference>
          <spring_stiffness>0.0</spring_stiffness>
        </dynamics>
        <limit>
          <lower>-1.57</lower>
          <upper>1.57</upper>
        </limit>
      </axis>
    </joint>


    <link name="arm_link_upperarm">
      <pose>0 0 0.29927009 1.570796327 1.570796327 0</pose>
      <gravity>1</gravity>
      <self_collide>0</self_collide>
      <kinematic>0</kinematic>

	  <inertial>
        <mass>0.10022841</mass>
        <inertia>
          <ixx>1.678e-05</ixx>
          <ixy>0</ixy>
          <ixz>0</ixz>
          <iyy>2.5428e-04</iyy>
          <iyz>0</iyz>
          <izz>2.4944e-04</izz>
        </inertia>
      </inertial>

      <collision name="collision_upperarm">
        <pose>-0.05197991 0 0 0 0 0</pose>
        <geometry>
          <box>
            <size>0.197 0.0285 0.041</size>
          </box>
        </geometry>
      </collision>

      <visual name="visual_upperarm_bracket">
        <pose>-0.15297991 0.012 0.0205 1.570796327 1.570796327 0</pose>
        <geometry>
		  <mesh>
			<uri>model://mantis_uav/meshes/FR12-H101.stl</uri>
			<scale>0.001 0.001 0.001</scale>
		  </mesh>
        </geometry>
        <material>
          <lighting>1</lighting>
          <script>
            <uri>file://media/materials/scripts/gazebo.material</uri>
            <name>Gazebo/Grey</name>
          </script>
        </material>
      </visual>

      <visual name="visual_upperarm_rod">
        <pose>-0.12247991 -0.008 -0.008 0 0 0</pose>
        <geometry>
		  <mesh>
			<uri>model://mantis_uav/meshes/rod.stl</uri>
			<scale>0.001 0.001 0.001</scale>
		  </mesh>
        </geometry>
        <material>
          <lighting>1</lighting>
          <script>
            <uri>file://media/materials/scripts/gazebo.material</uri>
            <name>Gazebo/Black</name>
          </script>
        </material>
      </visual>

      <visual name="visual_upperarm_servo">
        <pose>-0.00247991 0.01425 -0.019 0 0 -1.570796327</pose>
        <geometry>
		  <mesh>
			<uri>model://mantis_uav/meshes/X-430_IDLE.stl</uri>
			<scale>0.001 0.001 0.001</scale>
		  </mesh>
        </geometry>
        <material>
          <lighting>1</lighting>
          <script>
            <uri>file://media/materials/scripts/gazebo.material</uri>
            <name>Gazebo/DarkGrey</name>
          </script>
        </material>
      </visual>
    </link>


	<joint type="revolute" name="joint_elbow">
      <pose>-0.15047991 0 0 0 0 0</pose>
      <parent>arm_link_upperarm</parent>
      <child>arm_link_forearm</child>
      <axis>
        <xyz>0 0 1</xyz>
        <dynamics>
          <damping>0.01</damping>
          <spring_reference>0.0</spring_reference>
          <spring_stiffness>0.0</spring_stiffness>
        </dynamics>
        <limit>
          <lower>-1.57</lower>
          <upper>1.57</upper>
        </limit>
      </axis>
    </joint>


    <link name="arm_link_forearm">
      <pose>0 0 0.11602009 1.570796327 1.570796327 0</pose>
      <gravity>1</gravity>
      <self_collide>0</self_collide>
      <kinematic>0</kinematic>

	  <inertial>
        <mass>0.10022841</mass>
        <inertia>
          <ixx>1.678e-05</ixx>
          <ixy>0</ixy>
          <ixz>0</ixz>
          <iyy>2.5428e-04</iyy>
          <iyz>0</iyz>
          <izz>2.4944e-04</izz>
        </inertia>
      </inertial>

      <collision name="collision_forearm">
        <pose>-0.05197991 0 0 0 0 0</pose>
        <geometry>
          <box>
            <size>0.197 0.0285 0.041</size>
          </box>
        </geometry>
      </collision>

      <visual name="visual_forearm_bracket">
        <pose>-0.15297991 0.012 0.0205 1.570796327 1.570796327 0</pose>
        <geometry>
		  <mesh>
			<uri>model://mantis_uav/meshes/FR12-H101.stl</uri>
			<scale>0.001 0.001 0.001</scale>
		  </mesh>
        </geometry>
        <material>
          <lighting>1</lighting>
          <script>
            <uri>file://media/materials/scripts/gazebo.material</uri>
            <name>Gazebo/Grey</name>
          </script>
        </material>
      </visual>

      <visual name="visual_forearm_rod">
        <pose>-0.12247991 -0.008 -0.008 0 0 0</pose>
        <geometry>
		  <mesh>
			<uri>model://mantis_uav/meshes/rod.stl</uri>
			<scale>0.001 0.001 0.001</scale>
		  </mesh>
        </geometry>
        <material>
          <lighting>1</lighting>
          <script>
            <uri>file://media/materials/scripts/gazebo.material</uri>
            <name>Gazebo/Black</name>
          </script>
        </material>
      </visual>

      <visual name="visual_forearm_servo">
        <pose>-0.00247991 0.01425 -0.019 0 0 -1.570796327</pose>
        <geometry>
		  <mesh>
			<uri>model://mantis_uav/meshes/X-430_IDLE.stl</uri>
			<scale>0.001 0.001 0.001</scale>
		  </mesh>
        </geometry>
        <material>
          <lighting>1</lighting>
          <script>
            <uri>file://media/materials/scripts/gazebo.material</uri>
            <name>Gazebo/DarkGrey</name>
          </script>
        </material>
      </visual>
    </link>


    <link name='rotor_1'>
      <pose>0 -0.275 0.5455 0 0 0</pose>
      <gravity>1</gravity>
      <velocity_decay/>
      <self_collide>0</self_collide>

      <inertial>
        <mass>0.005</mass>
        <inertia>
          <ixx>9.75e-07</ixx>
          <ixy>0</ixy>
          <ixz>0</ixz>
          <iyy>0.000273104</iyy>
          <iyz>0</iyz>
          <izz>0.000274004</izz>
        </inertia>
      </inertial>

      <collision name='collision_rotor_1'>
        <geometry>
          <cylinder>
            <length>0.005</length>
            <radius>0.128</radius>
          </cylinder>
        </geometry>
      </collision>

      <visual name='visual_rotor_1'>
        <pose>0 0 -0.0036 0 0 0</pose>
        <geometry>
		  <mesh>
			<uri>model://mantis_uav/meshes/prop_8045_CW.stl</uri>
			<scale>0.001 0.001 0.001</scale>
		  </mesh>
        </geometry>
        <material>
          <script>
            <name>Gazebo/Black</name>
            <uri>file://media/materials/scripts/gazebo.material</uri>
          </script>
        </material>
      </visual>
    </link>


    <joint type='revolute' name='joint_rotor_1'>
      <child>rotor_1</child>
      <parent>base_link</parent>
      <axis>
        <xyz>0 0 1</xyz>
        <limit>
          <lower>-1e+16</lower>
          <upper>1e+16</upper>
        </limit>
        <use_parent_model_frame>1</use_parent_model_frame>
      </axis>
    </joint>


    <link name='rotor_2'>
      <pose>0 0.275 0.5475 0 0 0</pose>
      <gravity>1</gravity>
      <velocity_decay/>
      <self_collide>0</self_collide>

      <inertial>
        <mass>0.005</mass>
        <inertia>
          <ixx>9.75e-07</ixx>
          <ixy>0</ixy>
          <ixz>0</ixz>
          <iyy>0.000273104</iyy>
          <iyz>0</iyz>
          <izz>0.000274004</izz>
        </inertia>
      </inertial>

      <collision name='collision_rotor_2'>
        <geometry>
          <cylinder>
            <length>0.005</length>
            <radius>0.128</radius>
          </cylinder>
        </geometry>
      </collision>

      <visual name='visual_rotor_2'>
        <pose>0 0 -0.0036 0 0 0</pose>
        <geometry>
		  <mesh>
			<uri>model://mantis_uav/meshes/prop_8045_CCW.stl</uri>
			<scale>0.001 0.001 0.001</scale>
		  </mesh>
        </geometry>
        <material>
          <script>
            <name>Gazebo/Black</name>
            <uri>file://media/materials/scripts/gazebo.material</uri>
          </script>
        </material>
      </visual>
    </link>


    <joint type='revolute' name='joint_rotor_2'>
      <child>rotor_2</child>
      <parent>base_link</parent>
      <axis>
        <xyz>0 0 1</xyz>
        <limit>
          <lower>-1e+16</lower>
          <upper>1e+16</upper>
        </limit>
        <use_parent_model_frame>1</use_parent_model_frame>
      </axis>
    </joint>


    <link name='rotor_3'>
      <pose>0.2382 0.1375 0.5455 0 0 0</pose>
      <gravity>1</gravity>
      <velocity_decay/>
      <self_collide>0</self_collide>

      <inertial>
        <mass>0.005</mass>
        <inertia>
          <ixx>9.75e-07</ixx>
          <ixy>0</ixy>
          <ixz>0</ixz>
          <iyy>0.000273104</iyy>
          <iyz>0</iyz>
          <izz>0.000274004</izz>
        </inertia>
      </inertial>

      <collision name='collision_rotor_3'>
        <geometry>
          <cylinder>
            <length>0.005</length>
            <radius>0.128</radius>
          </cylinder>
        </geometry>
      </collision>

      <visual name='visual_rotor_3'>
        <pose>0 0 -0.0036 0 0 0</pose>
        <geometry>
		  <mesh>
			<uri>model://mantis_uav/meshes/prop_8045_CW.stl</uri>
			<scale>0.001 0.001 0.001</scale>
		  </mesh>
        </geometry>
        <material>
          <script>
            <name>Gazebo/Black</name>
            <uri>file://media/materials/scripts/gazebo.material</uri>
          </script>
        </material>
      </visual>
    </link>


    <joint type='revolute' name='joint_rotor_3'>
      <child>rotor_3</child>
      <parent>base_link</parent>
      <axis>
        <xyz>0 0 1</xyz>
        <limit>
          <lower>-1e+16</lower>
          <upper>1e+16</upper>
        </limit>
        <use_parent_model_frame>1</use_parent_model_frame>
      </axis>
    </joint>


    <link name='rotor_4'>
      <pose>-0.2382 -0.1375 0.5455 0 0 0</pose>
      <gravity>1</gravity>
      <velocity_decay/>
      <self_collide>0</self_collide>

      <inertial>
        <mass>0.005</mass>
        <inertia>
          <ixx>9.75e-07</ixx>
          <ixy>0</ixy>
          <ixz>0</ixz>
          <iyy>0.000273104</iyy>
          <iyz>0</iyz>
          <izz>0.000274004</izz>
        </inertia>
      </inertial>

      <collision name='collision_rotor_4'>
        <geometry>
          <cylinder>
            <length>0.005</length>
            <radius>0.128</radius>
          </cylinder>
        </geometry>
      </collision>

      <visual name='visual_rotor_4'>
        <pose>0 0 -0.0036 0 0 0</pose>
        <geometry>
		  <mesh>
			<uri>model://mantis_uav/meshes/prop_8045_CCW.stl</uri>
			<scale>0.001 0.001 0.001</scale>
		  </mesh>
        </geometry>
        <material>
          <script>
            <name>Gazebo/Black</name>
            <uri>file://media/materials/scripts/gazebo.material</uri>
          </script>
        </material>
      </visual>
    </link>


    <joint type='revolute' name='joint_rotor_4'>
      <child>rotor_4</child>
      <parent>base_link</parent>
      <axis>
        <xyz>0 0 1</xyz>
        <limit>
          <lower>-1e+16</lower>
          <upper>1e+16</upper>
        </limit>
        <use_parent_model_frame>1</use_parent_model_frame>
      </axis>
    </joint>


    <link name='rotor_5'>
      <pose>0.2382 -0.1375 0.5455 0 0 0</pose>
      <gravity>1</gravity>
      <velocity_decay/>
      <self_collide>0</self_collide>

      <inertial>
        <mass>0.005</mass>
        <inertia>
          <ixx>9.75e-07</ixx>
          <ixy>0</ixy>
          <ixz>0</ixz>
          <iyy>0.000273104</iyy>
          <iyz>0</iyz>
          <izz>0.000274004</izz>
        </inertia>
      </inertial>

      <collision name='collision_rotor_5'>
        <geometry>
          <cylinder>
            <length>0.005</length>
            <radius>0.128</radius>
          </cylinder>
        </geometry>
      </collision>

      <visual name='visual_rotor_5'>
        <pose>0 0 -0.0036 0 0 0</pose>
        <geometry>
		  <mesh>
			<uri>model://mantis_uav/meshes/prop_8045_CCW.stl</uri>
			<scale>0.001 0.001 0.001</scale>
		  </mesh>
        </geometry>
        <material>
          <script>
            <name>Gazebo/Black</name>
            <uri>file://media/materials/scripts/gazebo.material</uri>
          </script>
        </material>
      </visual>
    </link>


    <joint type='revolute' name='joint_rotor_5'>
      <child>rotor_5</child>
      <parent>base_link</parent>
      <axis>
        <xyz>0 0 1</xyz>
        <limit>
          <lower>-1e+16</lower>
          <upper>1e+16</upper>
        </limit>
        <use_parent_model_frame>1</use_parent_model_frame>
      </axis>
    </joint>


    <link name='rotor_6'>
      <pose>-0.2382 0.1375 0.5455 0 0 0</pose>
      <gravity>1</gravity>
      <velocity_decay/>
      <self_collide>0</self_collide>

      <inertial>
        <mass>0.005</mass>
        <inertia>
          <ixx>9.75e-07</ixx>
          <ixy>0</ixy>
          <ixz>0</ixz>
          <iyy>0.000273104</iyy>
          <iyz>0</iyz>
          <izz>0.000274004</izz>
        </inertia>
      </inertial>

      <collision name='collision_rotor_6'>
        <geometry>
          <cylinder>
            <length>0.005</length>
            <radius>0.128</radius>
          </cylinder>
        </geometry>
      </collision>

      <visual name='visual_rotor_6'>
        <pose>0 0 -0.0036 0 0 0</pose>
        <geometry>
		  <mesh>
			<uri>model://mantis_uav/meshes/prop_8045_CW.stl</uri>
			<scale>0.001 0.001 0.001</scale>
		  </mesh>
        </geometry>
        <material>
          <script>
            <name>Gazebo/Black</name>
            <uri>file://media/materials/scripts/gazebo.material</uri>
          </script>
        </material>
      </visual>
    </link>


    <joint type='revolute' name='joint_rotor_6'>
      <child>rotor_6</child>
      <parent>base_link</parent>
      <axis>
        <xyz>0 0 1</xyz>
        <limit>
          <lower>-1e+16</lower>
          <upper>1e+16</upper>
        </limit>
        <use_parent_model_frame>1</use_parent_model_frame>
      </axis>
    </joint>


    <plugin name="mantis_gazebo_servo" filename="libmantis_gazebo_servo.so"/>

    <plugin name="mantis_gazebo_pwm" filename="libmantis_gazebo_pwm_motor.so"/>

    <plugin name="mantis_gazebo_safety" filename="libmantis_gazebo_safety.so"/>

    <plugin name="imu_plugin" filename="libhector_gazebo_ros_imu.so">
      <alwaysOn>true</alwaysOn>
      <frameName>world</frameName>
      <bodyName>base_link</bodyName>
      <topicName>mantis_uav/imu_data</topicName>
      <serviceName>mantis_uav/imu_service</serviceName>
      <gaussianNoise>0.0</gaussianNoise>
      <updateRate>500.0</updateRate>
    </plugin>

	<plugin name='mantis_gazebo_motor_model_1' filename='libmantis_gazebo_motor_model.so'>
      <robotNamespace></robotNamespace>
      <jointName>joint_rotor_1</jointName>
      <linkName>rotor_1</linkName>
      <turningDirection>cw</turningDirection>
      <timeConstantUp>0.0125</timeConstantUp>
      <timeConstantDown>0.025</timeConstantDown>
      <maxRotVelocity>1618</maxRotVelocity>
      <motorConstant>4.019e-06</motorConstant>
      <momentConstant>0.06</momentConstant>
      <commandSubTopic>/command/motor_velocity</commandSubTopic>
      <motorNumber>0</motorNumber>
      <rotorDragCoefficient>0.000806428</rotorDragCoefficient>
      <rollingMomentCoefficient>1e-06</rollingMomentCoefficient>
      <motorSpeedPubTopic>/state/motor_speed/1</motorSpeedPubTopic>
      <rotorVelocitySlowdownSim>10</rotorVelocitySlowdownSim>
    </plugin>

	<plugin name='mantis_gazebo_motor_model_2' filename='libmantis_gazebo_motor_model.so'>
      <robotNamespace></robotNamespace>
      <jointName>joint_rotor_2</jointName>
      <linkName>rotor_2</linkName>
      <turningDirection>ccw</turningDirection>
      <timeConstantUp>0.0125</timeConstantUp>
      <timeConstantDown>0.025</timeConstantDown>
      <maxRotVelocity>1618</maxRotVelocity>
      <motorConstant>4.019e-06</motorConstant>
      <momentConstant>0.06</momentConstant>
      <commandSubTopic>/command/motor_velocity</commandSubTopic>
      <motorNumber>1</motorNumber>
      <rotorDragCoefficient>0.000806428</rotorDragCoefficient>
      <rollingMomentCoefficient>1e-06</rollingMomentCoefficient>
      <motorSpeedPubTopic>/state/motor_speed/2</motorSpeedPubTopic>
      <rotorVelocitySlowdownSim>10</rotorVelocitySlowdownSim>
    </plugin>

	<plugin name='mantis_gazebo_motor_model_3' filename='libmantis_gazebo_motor_model.so'>
      <robotNamespace></robotNamespace>
      <jointName>joint_rotor_3</jointName>
      <linkName>rotor_3</linkName>
      <turningDirection>cw</turningDirection>
      <timeConstantUp>0.0125</timeConstantUp>
      <timeConstantDown>0.025</timeConstantDown>
      <maxRotVelocity>1618</maxRotVelocity>
      <motorConstant>4.019e-06</motorConstant>
      <momentConstant>0.06</momentConstant>
      <commandSubTopic>/command/motor_velocity</commandSubTopic>
      <motorNumber>2</motorNumber>
      <rotorDragCoefficient>0.000806428</rotorDragCoefficient>
      <rollingMomentCoefficient>1e-06</rollingMomentCoefficient>
      <motorSpeedPubTopic>/state/motor_speed/3</motorSpeedPubTopic>
      <rotorVelocitySlowdownSim>10</rotorVelocitySlowdownSim>
    </plugin>

	<plugin name='mantis_gazebo_motor_model_4' filename='libmantis_gazebo_motor_model.so'>
      <robotNamespace></robotNamespace>
      <jointName>joint_rotor_4</jointName>
      <linkName>rotor_4</linkName>
      <turningDirection>ccw</turningDirection>
      <timeConstantUp>0.0125</timeConstantUp>
      <timeConstantDown>0.025</timeConstantDown>
      <maxRotVelocity>1618</maxRotVelocity>
      <motorConstant>4.019e-06</motorConstant>
      <momentConstant>0.06</momentConstant>
      <commandSubTopic>/command/motor_velocity</commandSubTopic>
      <motorNumber>3</motorNumber>
      <rotorDragCoefficient>0.000806428</rotorDragCoefficient>
      <rollingMomentCoefficient>1e-06</rollingMomentCoefficient>
      <motorSpeedPubTopic>/state/motor_speed/4</motorSpeedPubTopic>
      <rotorVelocitySlowdownSim>10</rotorVelocitySlowdownSim>
    </plugin>

	<plugin name='mantis_gazebo_motor_model_5' filename='libmantis_gazebo_motor_model.so'>
      <robotNamespace></robotNamespace>
      <jointName>joint_rotor_5</jointName>
      <linkName>rotor_5</linkName>
      <turningDirection>ccw</turningDirection>
      <timeConstantUp>0.0125</timeConstantUp>
      <timeConstantDown>0.025</timeConstantDown>
      <maxRotVelocity>1618</maxRotVelocity>
      <motorConstant>4.019e-06</motorConstant>
      <momentConstant>0.06</momentConstant>
      <commandSubTopic>/command/motor_velocity</commandSubTopic>
      <motorNumber>4</motorNumber>
      <rotorDragCoefficient>0.000806428</rotorDragCoefficient>
      <rollingMomentCoefficient>1e-06</rollingMomentCoefficient>
      <motorSpeedPubTopic>/state/motor_speed/5</motorSpeedPubTopic>
      <rotorVelocitySlowdownSim>10</rotorVelocitySlowdownSim>
    </plugin>

	<plugin name='mantis_gazebo_motor_model_6' filename='libmantis_gazebo_motor_model.so'>
      <robotNamespace></robotNamespace>
      <jointName>joint_rotor_6</jointName>
      <linkName>rotor_6</linkName>
      <turningDirection>cw</turningDirection>
      <timeConstantUp>0.0125</timeConstantUp>
      <timeConstantDown>0.025</timeConstantDown>
      <maxRotVelocity>1618</maxRotVelocity>
      <motorConstant>4.019e-06</motorConstant>
      <momentConstant>0.06</momentConstant>
      <commandSubTopic>/command/motor_velocity</commandSubTopic>
      <motorNumber>5</motorNumber>
      <rotorDragCoefficient>0.000806428</rotorDragCoefficient>
      <rollingMomentCoefficient>1e-06</rollingMomentCoefficient>
      <motorSpeedPubTopic>/state/motor_speed/6</motorSpeedPubTopic>
      <rotorVelocitySlowdownSim>10</rotorVelocitySlowdownSim>
    </plugin>

    <static>false</static>
    <allow_auto_disable>1</allow_auto_disable>
  </model>
</sdf>
